try {
  // Produce a ReferenceError
  myFunction();
} catch (e) {
  console.log(e);
}

console.log('Program Continues...');